INFO:2023-12-28 14:59:39,841:magicstore:914:Starting 914 browser profile
INFO:2023-12-28 14:59:52,797:magicstore:914:Connecting to browser: ws://127.0.0.1:59544/devtools/browser/90145188-ac5c-431b-a037-0dc5eafc8836
  | ExceptionGroup: all attempts to connect to 127.0.0.1:59544 failed (1 sub-exception)
  +-+---------------- 1 ----------------
    | Traceback (most recent call last):
    |   File "C:\Python\Lib\site-packages\trio\_highlevel_open_tcp_stream.py", line 360, in attempt_connect
    |     await sock.connect(sockaddr)
    |   File "C:\Python\Lib\site-packages\trio\_socket.py", line 1046, in connect
    |     raise OSError(err, f"Error connecting to {address!r}: {os.strerror(err)}")
    | ConnectionRefusedError: [Errno 10061] Error connecting to ('127.0.0.1', 59544): Unknown error
    +------------------------------------

The above exception was the direct cause of the following exception:

Traceback (most recent call last):
  File "C:\Users\Administrator\magicstore\asd.py", line 416, in worker
    async with open_cdp(cdp_uri) as conn:
  File "C:\Python\Lib\contextlib.py", line 204, in __aenter__
    return await anext(self.gen)
           ^^^^^^^^^^^^^^^^^^^^^
  File "C:\Python\Lib\site-packages\trio_cdp\__init__.py", line 368, in open_cdp
    conn = await connect_cdp(nursery, url)
           ^^^^^^^^^^^^^^^^^^^^^^^^^^^^^^^
  File "C:\Python\Lib\site-packages\trio_cdp\__init__.py", line 392, in connect_cdp
    ws = await connect_websocket_url(nursery, url,
         ^^^^^^^^^^^^^^^^^^^^^^^^^^^^^^^^^^^^^^^^^
  File "C:\Python\Lib\site-packages\trio_websocket\_impl.py", line 232, in connect_websocket_url
    return await connect_websocket(nursery, host, port, resource,
           ^^^^^^^^^^^^^^^^^^^^^^^^^^^^^^^^^^^^^^^^^^^^^^^^^^^^^^
  File "C:\Python\Lib\site-packages\trio_websocket\_impl.py", line 141, in connect_websocket
    stream = await trio.open_tcp_stream(host, port)
             ^^^^^^^^^^^^^^^^^^^^^^^^^^^^^^^^^^^^^^
  File "C:\Python\Lib\site-packages\trio\_highlevel_open_tcp_stream.py", line 404, in open_tcp_stream
    raise OSError(msg) from ExceptionGroup(msg, oserrors)
OSError: all attempts to connect to 127.0.0.1:59544 failed

During handling of the above exception, another exception occurred:

Traceback (most recent call last):
  File "C:\Users\Administrator\magicstore\asd.py", line 470, in <module>
    trio.run(worker, sys.argv[1], restrict_keyboard_interrupt_to_checkpoints=True)
  File "C:\Python\Lib\site-packages\trio\_core\_run.py", line 2262, in run
    raise runner.main_task_outcome.error
  File "C:\Users\Administrator\magicstore\asd.py", line 448, in worker
    ads_request('/api/v1/browser/stop', user_id=acc['user_id'])
  File "C:\Users\Administrator\magicstore\utils.py", line 75, in ads_request
    raise RuntimeError(json['msg'])
RuntimeError: {}
